Not Found: /favicon.ico
Internal Server Error: /admin/registerUser/user/1/change/
Traceback (most recent call last):
  File "/Users/richellekyj/opt/anaconda3/lib/python3.8/site-packages/django/contrib/admin/options.py", line 710, in get_form
    return modelform_factory(self.model, **defaults)
  File "/Users/richellekyj/opt/anaconda3/lib/python3.8/site-packages/django/forms/models.py", line 563, in modelform_factory
    return type(form)(class_name, (form,), form_class_attrs)
  File "/Users/richellekyj/opt/anaconda3/lib/python3.8/site-packages/django/forms/models.py", line 276, in __new__
    raise FieldError(message)
django.core.exceptions.FieldError: Unknown field(s) (role) specified for User

During handling of the above exception, another exception occurred:

Traceback (most recent call last):
  File "/Users/richellekyj/opt/anaconda3/lib/python3.8/site-packages/django/core/handlers/exception.py", line 47, in inner
    response = get_response(request)
  File "/Users/richellekyj/opt/anaconda3/lib/python3.8/site-packages/django/core/handlers/base.py", line 181, in _get_response
    response = wrapped_callback(request, *callback_args, **callback_kwargs)
  File "/Users/richellekyj/opt/anaconda3/lib/python3.8/site-packages/django/contrib/admin/options.py", line 616, in wrapper
    return self.admin_site.admin_view(view)(*args, **kwargs)
  File "/Users/richellekyj/opt/anaconda3/lib/python3.8/site-packages/django/utils/decorators.py", line 130, in _wrapped_view
    response = view_func(request, *args, **kwargs)
  File "/Users/richellekyj/opt/anaconda3/lib/python3.8/site-packages/django/views/decorators/cache.py", line 44, in _wrapped_view_func
    response = view_func(request, *args, **kwargs)
  File "/Users/richellekyj/opt/anaconda3/lib/python3.8/site-packages/django/contrib/admin/sites.py", line 232, in inner
    return view(request, *args, **kwargs)
  File "/Users/richellekyj/opt/anaconda3/lib/python3.8/site-packages/django/contrib/admin/options.py", line 1658, in change_view
    return self.changeform_view(request, object_id, form_url, extra_context)
  File "/Users/richellekyj/opt/anaconda3/lib/python3.8/site-packages/django/utils/decorators.py", line 43, in _wrapper
    return bound_method(*args, **kwargs)
  File "/Users/richellekyj/opt/anaconda3/lib/python3.8/site-packages/django/utils/decorators.py", line 130, in _wrapped_view
    response = view_func(request, *args, **kwargs)
  File "/Users/richellekyj/opt/anaconda3/lib/python3.8/site-packages/django/contrib/admin/options.py", line 1538, in changeform_view
    return self._changeform_view(request, object_id, form_url, extra_context)
  File "/Users/richellekyj/opt/anaconda3/lib/python3.8/site-packages/django/contrib/admin/options.py", line 1572, in _changeform_view
    ModelForm = self.get_form(
  File "/Users/richellekyj/opt/anaconda3/lib/python3.8/site-packages/django/contrib/auth/admin.py", line 80, in get_form
    return super().get_form(request, obj, **defaults)
  File "/Users/richellekyj/opt/anaconda3/lib/python3.8/site-packages/django/contrib/admin/options.py", line 712, in get_form
    raise FieldError(
django.core.exceptions.FieldError: Unknown field(s) (role) specified for User. Check fields/fieldsets/exclude attributes of class UserAdmin.
Internal Server Error: /admin/registerUser/user/add/
Traceback (most recent call last):
  File "/Users/richellekyj/opt/anaconda3/lib/python3.8/site-packages/django/db/backends/utils.py", line 84, in _execute
    return self.cursor.execute(sql, params)
  File "/Users/richellekyj/opt/anaconda3/lib/python3.8/site-packages/django/db/backends/mysql/base.py", line 73, in execute
    return self.cursor.execute(query, args)
  File "/Users/richellekyj/opt/anaconda3/lib/python3.8/site-packages/MySQLdb/cursors.py", line 206, in execute
    res = self._query(query)
  File "/Users/richellekyj/opt/anaconda3/lib/python3.8/site-packages/MySQLdb/cursors.py", line 319, in _query
    db.query(q)
  File "/Users/richellekyj/opt/anaconda3/lib/python3.8/site-packages/MySQLdb/connections.py", line 259, in query
    _mysql.connection.query(self, query)
MySQLdb._exceptions.IntegrityError: (1062, "Duplicate entry '' for key 'registeruser_user.email'")

The above exception was the direct cause of the following exception:

Traceback (most recent call last):
  File "/Users/richellekyj/opt/anaconda3/lib/python3.8/site-packages/django/core/handlers/exception.py", line 47, in inner
    response = get_response(request)
  File "/Users/richellekyj/opt/anaconda3/lib/python3.8/site-packages/django/core/handlers/base.py", line 181, in _get_response
    response = wrapped_callback(request, *callback_args, **callback_kwargs)
  File "/Users/richellekyj/opt/anaconda3/lib/python3.8/site-packages/django/contrib/admin/options.py", line 616, in wrapper
    return self.admin_site.admin_view(view)(*args, **kwargs)
  File "/Users/richellekyj/opt/anaconda3/lib/python3.8/site-packages/django/utils/decorators.py", line 130, in _wrapped_view
    response = view_func(request, *args, **kwargs)
  File "/Users/richellekyj/opt/anaconda3/lib/python3.8/site-packages/django/views/decorators/cache.py", line 44, in _wrapped_view_func
    response = view_func(request, *args, **kwargs)
  File "/Users/richellekyj/opt/anaconda3/lib/python3.8/site-packages/django/contrib/admin/sites.py", line 232, in inner
    return view(request, *args, **kwargs)
  File "/Users/richellekyj/opt/anaconda3/lib/python3.8/site-packages/django/utils/decorators.py", line 43, in _wrapper
    return bound_method(*args, **kwargs)
  File "/Users/richellekyj/opt/anaconda3/lib/python3.8/site-packages/django/views/decorators/debug.py", line 89, in sensitive_post_parameters_wrapper
    return view(request, *args, **kwargs)
  File "/Users/richellekyj/opt/anaconda3/lib/python3.8/site-packages/django/utils/decorators.py", line 43, in _wrapper
    return bound_method(*args, **kwargs)
  File "/Users/richellekyj/opt/anaconda3/lib/python3.8/site-packages/django/utils/decorators.py", line 130, in _wrapped_view
    response = view_func(request, *args, **kwargs)
  File "/Users/richellekyj/opt/anaconda3/lib/python3.8/site-packages/django/contrib/auth/admin.py", line 99, in add_view
    return self._add_view(request, form_url, extra_context)
  File "/Users/richellekyj/opt/anaconda3/lib/python3.8/site-packages/django/contrib/auth/admin.py", line 126, in _add_view
    return super().add_view(request, form_url, extra_context)
  File "/Users/richellekyj/opt/anaconda3/lib/python3.8/site-packages/django/contrib/admin/options.py", line 1655, in add_view
    return self.changeform_view(request, None, form_url, extra_context)
  File "/Users/richellekyj/opt/anaconda3/lib/python3.8/site-packages/django/utils/decorators.py", line 43, in _wrapper
    return bound_method(*args, **kwargs)
  File "/Users/richellekyj/opt/anaconda3/lib/python3.8/site-packages/django/utils/decorators.py", line 130, in _wrapped_view
    response = view_func(request, *args, **kwargs)
  File "/Users/richellekyj/opt/anaconda3/lib/python3.8/site-packages/django/contrib/admin/options.py", line 1538, in changeform_view
    return self._changeform_view(request, object_id, form_url, extra_context)
  File "/Users/richellekyj/opt/anaconda3/lib/python3.8/site-packages/django/contrib/admin/options.py", line 1584, in _changeform_view
    self.save_model(request, new_object, form, not add)
  File "/Users/richellekyj/opt/anaconda3/lib/python3.8/site-packages/django/contrib/admin/options.py", line 1097, in save_model
    obj.save()
  File "/Users/richellekyj/opt/anaconda3/lib/python3.8/site-packages/django/contrib/auth/base_user.py", line 67, in save
    super().save(*args, **kwargs)
  File "/Users/richellekyj/opt/anaconda3/lib/python3.8/site-packages/django/db/models/base.py", line 726, in save
    self.save_base(using=using, force_insert=force_insert,
  File "/Users/richellekyj/opt/anaconda3/lib/python3.8/site-packages/django/db/models/base.py", line 763, in save_base
    updated = self._save_table(
  File "/Users/richellekyj/opt/anaconda3/lib/python3.8/site-packages/django/db/models/base.py", line 868, in _save_table
    results = self._do_insert(cls._base_manager, using, fields, returning_fields, raw)
  File "/Users/richellekyj/opt/anaconda3/lib/python3.8/site-packages/django/db/models/base.py", line 906, in _do_insert
    return manager._insert(
  File "/Users/richellekyj/opt/anaconda3/lib/python3.8/site-packages/django/db/models/manager.py", line 85, in manager_method
    return getattr(self.get_queryset(), name)(*args, **kwargs)
  File "/Users/richellekyj/opt/anaconda3/lib/python3.8/site-packages/django/db/models/query.py", line 1270, in _insert
    return query.get_compiler(using=using).execute_sql(returning_fields)
  File "/Users/richellekyj/opt/anaconda3/lib/python3.8/site-packages/django/db/models/sql/compiler.py", line 1410, in execute_sql
    cursor.execute(sql, params)
  File "/Users/richellekyj/opt/anaconda3/lib/python3.8/site-packages/django/db/backends/utils.py", line 98, in execute
    return super().execute(sql, params)
  File "/Users/richellekyj/opt/anaconda3/lib/python3.8/site-packages/django/db/backends/utils.py", line 66, in execute
    return self._execute_with_wrappers(sql, params, many=False, executor=self._execute)
  File "/Users/richellekyj/opt/anaconda3/lib/python3.8/site-packages/django/db/backends/utils.py", line 75, in _execute_with_wrappers
    return executor(sql, params, many, context)
  File "/Users/richellekyj/opt/anaconda3/lib/python3.8/site-packages/django/db/backends/utils.py", line 84, in _execute
    return self.cursor.execute(sql, params)
  File "/Users/richellekyj/opt/anaconda3/lib/python3.8/site-packages/django/db/utils.py", line 90, in __exit__
    raise dj_exc_value.with_traceback(traceback) from exc_value
  File "/Users/richellekyj/opt/anaconda3/lib/python3.8/site-packages/django/db/backends/utils.py", line 84, in _execute
    return self.cursor.execute(sql, params)
  File "/Users/richellekyj/opt/anaconda3/lib/python3.8/site-packages/django/db/backends/mysql/base.py", line 73, in execute
    return self.cursor.execute(query, args)
  File "/Users/richellekyj/opt/anaconda3/lib/python3.8/site-packages/MySQLdb/cursors.py", line 206, in execute
    res = self._query(query)
  File "/Users/richellekyj/opt/anaconda3/lib/python3.8/site-packages/MySQLdb/cursors.py", line 319, in _query
    db.query(q)
  File "/Users/richellekyj/opt/anaconda3/lib/python3.8/site-packages/MySQLdb/connections.py", line 259, in query
    _mysql.connection.query(self, query)
django.db.utils.IntegrityError: (1062, "Duplicate entry '' for key 'registeruser_user.email'")
Not Found: /admin.
Internal Server Error: /registerUser/
Traceback (most recent call last):
  File "/Users/richellekyj/opt/anaconda3/lib/python3.8/site-packages/django/core/handlers/exception.py", line 47, in inner
    response = get_response(request)
  File "/Users/richellekyj/opt/anaconda3/lib/python3.8/site-packages/django/core/handlers/base.py", line 181, in _get_response
    response = wrapped_callback(request, *callback_args, **callback_kwargs)
  File "/Users/richellekyj/Documents/FYP/OAiES/registerUser/views.py", line 15, in registerUser
    return render(request, 'registerUser.html', {})
  File "/Users/richellekyj/opt/anaconda3/lib/python3.8/site-packages/django/shortcuts.py", line 19, in render
    content = loader.render_to_string(template_name, context, request, using=using)
  File "/Users/richellekyj/opt/anaconda3/lib/python3.8/site-packages/django/template/loader.py", line 62, in render_to_string
    return template.render(context, request)
  File "/Users/richellekyj/opt/anaconda3/lib/python3.8/site-packages/django/template/backends/django.py", line 61, in render
    return self.template.render(context)
  File "/Users/richellekyj/opt/anaconda3/lib/python3.8/site-packages/django/template/base.py", line 170, in render
    return self._render(context)
  File "/Users/richellekyj/opt/anaconda3/lib/python3.8/site-packages/django/template/base.py", line 162, in _render
    return self.nodelist.render(context)
  File "/Users/richellekyj/opt/anaconda3/lib/python3.8/site-packages/django/template/base.py", line 938, in render
    bit = node.render_annotated(context)
  File "/Users/richellekyj/opt/anaconda3/lib/python3.8/site-packages/django/template/base.py", line 905, in render_annotated
    return self.render(context)
  File "/Users/richellekyj/opt/anaconda3/lib/python3.8/site-packages/django/template/library.py", line 192, in render
    output = self.func(*resolved_args, **resolved_kwargs)
  File "/Users/richellekyj/opt/anaconda3/lib/python3.8/site-packages/rest_framework/templatetags/rest_framework.py", line 81, in render_form
    return renderer.render(serializer.data, None, {'style': style})
AttributeError: 'str' object has no attribute 'data'
Internal Server Error: /registerUser/
Traceback (most recent call last):
  File "/Users/richellekyj/opt/anaconda3/lib/python3.8/site-packages/django/core/handlers/exception.py", line 47, in inner
    response = get_response(request)
  File "/Users/richellekyj/opt/anaconda3/lib/python3.8/site-packages/django/core/handlers/base.py", line 181, in _get_response
    response = wrapped_callback(request, *callback_args, **callback_kwargs)
  File "/Users/richellekyj/Documents/FYP/OAiES/registerUser/views.py", line 15, in registerUser
    return render(request, 'registerUser.html', context)
  File "/Users/richellekyj/opt/anaconda3/lib/python3.8/site-packages/django/shortcuts.py", line 19, in render
    content = loader.render_to_string(template_name, context, request, using=using)
  File "/Users/richellekyj/opt/anaconda3/lib/python3.8/site-packages/django/template/loader.py", line 62, in render_to_string
    return template.render(context, request)
  File "/Users/richellekyj/opt/anaconda3/lib/python3.8/site-packages/django/template/backends/django.py", line 61, in render
    return self.template.render(context)
  File "/Users/richellekyj/opt/anaconda3/lib/python3.8/site-packages/django/template/base.py", line 170, in render
    return self._render(context)
  File "/Users/richellekyj/opt/anaconda3/lib/python3.8/site-packages/django/template/base.py", line 162, in _render
    return self.nodelist.render(context)
  File "/Users/richellekyj/opt/anaconda3/lib/python3.8/site-packages/django/template/base.py", line 938, in render
    bit = node.render_annotated(context)
  File "/Users/richellekyj/opt/anaconda3/lib/python3.8/site-packages/django/template/base.py", line 905, in render_annotated
    return self.render(context)
  File "/Users/richellekyj/opt/anaconda3/lib/python3.8/site-packages/django/template/library.py", line 192, in render
    output = self.func(*resolved_args, **resolved_kwargs)
  File "/Users/richellekyj/opt/anaconda3/lib/python3.8/site-packages/rest_framework/templatetags/rest_framework.py", line 81, in render_form
    return renderer.render(serializer.data, None, {'style': style})
AttributeError: 'str' object has no attribute 'data'
Internal Server Error: /registerUser/
Traceback (most recent call last):
  File "/Users/richellekyj/opt/anaconda3/lib/python3.8/site-packages/django/core/handlers/exception.py", line 47, in inner
    response = get_response(request)
  File "/Users/richellekyj/opt/anaconda3/lib/python3.8/site-packages/django/core/handlers/base.py", line 181, in _get_response
    response = wrapped_callback(request, *callback_args, **callback_kwargs)
  File "/Users/richellekyj/Documents/FYP/OAiES/registerUser/views.py", line 15, in registerUser
    return render(request, 'registerUser.html', context)
  File "/Users/richellekyj/opt/anaconda3/lib/python3.8/site-packages/django/shortcuts.py", line 19, in render
    content = loader.render_to_string(template_name, context, request, using=using)
  File "/Users/richellekyj/opt/anaconda3/lib/python3.8/site-packages/django/template/loader.py", line 62, in render_to_string
    return template.render(context, request)
  File "/Users/richellekyj/opt/anaconda3/lib/python3.8/site-packages/django/template/backends/django.py", line 61, in render
    return self.template.render(context)
  File "/Users/richellekyj/opt/anaconda3/lib/python3.8/site-packages/django/template/base.py", line 170, in render
    return self._render(context)
  File "/Users/richellekyj/opt/anaconda3/lib/python3.8/site-packages/django/template/base.py", line 162, in _render
    return self.nodelist.render(context)
  File "/Users/richellekyj/opt/anaconda3/lib/python3.8/site-packages/django/template/base.py", line 938, in render
    bit = node.render_annotated(context)
  File "/Users/richellekyj/opt/anaconda3/lib/python3.8/site-packages/django/template/base.py", line 905, in render_annotated
    return self.render(context)
  File "/Users/richellekyj/opt/anaconda3/lib/python3.8/site-packages/django/template/library.py", line 192, in render
    output = self.func(*resolved_args, **resolved_kwargs)
  File "/Users/richellekyj/opt/anaconda3/lib/python3.8/site-packages/rest_framework/templatetags/rest_framework.py", line 81, in render_form
    return renderer.render(serializer.data, None, {'style': style})
AttributeError: 'str' object has no attribute 'data'
Internal Server Error: /registerUser/
Traceback (most recent call last):
  File "/Users/richellekyj/opt/anaconda3/lib/python3.8/site-packages/django/core/handlers/exception.py", line 47, in inner
    response = get_response(request)
  File "/Users/richellekyj/opt/anaconda3/lib/python3.8/site-packages/django/core/handlers/base.py", line 181, in _get_response
    response = wrapped_callback(request, *callback_args, **callback_kwargs)
  File "/Users/richellekyj/Documents/FYP/OAiES/registerUser/views.py", line 15, in registerUser
    return render(request, 'registerUser.html', context)
  File "/Users/richellekyj/opt/anaconda3/lib/python3.8/site-packages/django/shortcuts.py", line 19, in render
    content = loader.render_to_string(template_name, context, request, using=using)
  File "/Users/richellekyj/opt/anaconda3/lib/python3.8/site-packages/django/template/loader.py", line 62, in render_to_string
    return template.render(context, request)
  File "/Users/richellekyj/opt/anaconda3/lib/python3.8/site-packages/django/template/backends/django.py", line 61, in render
    return self.template.render(context)
  File "/Users/richellekyj/opt/anaconda3/lib/python3.8/site-packages/django/template/base.py", line 170, in render
    return self._render(context)
  File "/Users/richellekyj/opt/anaconda3/lib/python3.8/site-packages/django/template/base.py", line 162, in _render
    return self.nodelist.render(context)
  File "/Users/richellekyj/opt/anaconda3/lib/python3.8/site-packages/django/template/base.py", line 938, in render
    bit = node.render_annotated(context)
  File "/Users/richellekyj/opt/anaconda3/lib/python3.8/site-packages/django/template/base.py", line 905, in render_annotated
    return self.render(context)
  File "/Users/richellekyj/opt/anaconda3/lib/python3.8/site-packages/django/template/library.py", line 192, in render
    output = self.func(*resolved_args, **resolved_kwargs)
  File "/Users/richellekyj/opt/anaconda3/lib/python3.8/site-packages/rest_framework/templatetags/rest_framework.py", line 81, in render_form
    return renderer.render(serializer.data, None, {'style': style})
AttributeError: 'str' object has no attribute 'data'
Internal Server Error: /registerUser/
Traceback (most recent call last):
  File "/Users/richellekyj/opt/anaconda3/lib/python3.8/site-packages/django/core/handlers/exception.py", line 47, in inner
    response = get_response(request)
  File "/Users/richellekyj/opt/anaconda3/lib/python3.8/site-packages/django/core/handlers/base.py", line 181, in _get_response
    response = wrapped_callback(request, *callback_args, **callback_kwargs)
  File "/Users/richellekyj/Documents/FYP/OAiES/registerUser/views.py", line 16, in registerUser
    return render(request, 'registerUser.html', context)
  File "/Users/richellekyj/opt/anaconda3/lib/python3.8/site-packages/django/shortcuts.py", line 19, in render
    content = loader.render_to_string(template_name, context, request, using=using)
  File "/Users/richellekyj/opt/anaconda3/lib/python3.8/site-packages/django/template/loader.py", line 62, in render_to_string
    return template.render(context, request)
  File "/Users/richellekyj/opt/anaconda3/lib/python3.8/site-packages/django/template/backends/django.py", line 61, in render
    return self.template.render(context)
  File "/Users/richellekyj/opt/anaconda3/lib/python3.8/site-packages/django/template/base.py", line 170, in render
    return self._render(context)
  File "/Users/richellekyj/opt/anaconda3/lib/python3.8/site-packages/django/template/base.py", line 162, in _render
    return self.nodelist.render(context)
  File "/Users/richellekyj/opt/anaconda3/lib/python3.8/site-packages/django/template/base.py", line 938, in render
    bit = node.render_annotated(context)
  File "/Users/richellekyj/opt/anaconda3/lib/python3.8/site-packages/django/template/base.py", line 905, in render_annotated
    return self.render(context)
  File "/Users/richellekyj/opt/anaconda3/lib/python3.8/site-packages/django/template/library.py", line 192, in render
    output = self.func(*resolved_args, **resolved_kwargs)
  File "/Users/richellekyj/opt/anaconda3/lib/python3.8/site-packages/rest_framework/templatetags/rest_framework.py", line 81, in render_form
    return renderer.render(serializer.data, None, {'style': style})
AttributeError: 'str' object has no attribute 'data'
Internal Server Error: /registerUser/
Traceback (most recent call last):
  File "/Users/richellekyj/opt/anaconda3/lib/python3.8/site-packages/django/core/handlers/exception.py", line 47, in inner
    response = get_response(request)
  File "/Users/richellekyj/opt/anaconda3/lib/python3.8/site-packages/django/core/handlers/base.py", line 181, in _get_response
    response = wrapped_callback(request, *callback_args, **callback_kwargs)
  File "/Users/richellekyj/Documents/FYP/OAiES/registerUser/views.py", line 16, in registerUser
    return render(request, 'registerUser.html', context)
  File "/Users/richellekyj/opt/anaconda3/lib/python3.8/site-packages/django/shortcuts.py", line 19, in render
    content = loader.render_to_string(template_name, context, request, using=using)
  File "/Users/richellekyj/opt/anaconda3/lib/python3.8/site-packages/django/template/loader.py", line 62, in render_to_string
    return template.render(context, request)
  File "/Users/richellekyj/opt/anaconda3/lib/python3.8/site-packages/django/template/backends/django.py", line 61, in render
    return self.template.render(context)
  File "/Users/richellekyj/opt/anaconda3/lib/python3.8/site-packages/django/template/base.py", line 170, in render
    return self._render(context)
  File "/Users/richellekyj/opt/anaconda3/lib/python3.8/site-packages/django/template/base.py", line 162, in _render
    return self.nodelist.render(context)
  File "/Users/richellekyj/opt/anaconda3/lib/python3.8/site-packages/django/template/base.py", line 938, in render
    bit = node.render_annotated(context)
  File "/Users/richellekyj/opt/anaconda3/lib/python3.8/site-packages/django/template/base.py", line 905, in render_annotated
    return self.render(context)
  File "/Users/richellekyj/opt/anaconda3/lib/python3.8/site-packages/django/template/library.py", line 192, in render
    output = self.func(*resolved_args, **resolved_kwargs)
  File "/Users/richellekyj/opt/anaconda3/lib/python3.8/site-packages/rest_framework/templatetags/rest_framework.py", line 81, in render_form
    return renderer.render(serializer.data, None, {'style': style})
AttributeError: 'str' object has no attribute 'data'
Internal Server Error: /registerUser/
Traceback (most recent call last):
  File "/Users/richellekyj/opt/anaconda3/lib/python3.8/site-packages/django/core/handlers/exception.py", line 47, in inner
    response = get_response(request)
  File "/Users/richellekyj/opt/anaconda3/lib/python3.8/site-packages/django/core/handlers/base.py", line 181, in _get_response
    response = wrapped_callback(request, *callback_args, **callback_kwargs)
  File "/Users/richellekyj/Documents/FYP/OAiES/registerUser/views.py", line 16, in registerUser
    return render(request, 'registerUser.html', context)
  File "/Users/richellekyj/opt/anaconda3/lib/python3.8/site-packages/django/shortcuts.py", line 19, in render
    content = loader.render_to_string(template_name, context, request, using=using)
  File "/Users/richellekyj/opt/anaconda3/lib/python3.8/site-packages/django/template/loader.py", line 62, in render_to_string
    return template.render(context, request)
  File "/Users/richellekyj/opt/anaconda3/lib/python3.8/site-packages/django/template/backends/django.py", line 61, in render
    return self.template.render(context)
  File "/Users/richellekyj/opt/anaconda3/lib/python3.8/site-packages/django/template/base.py", line 170, in render
    return self._render(context)
  File "/Users/richellekyj/opt/anaconda3/lib/python3.8/site-packages/django/template/base.py", line 162, in _render
    return self.nodelist.render(context)
  File "/Users/richellekyj/opt/anaconda3/lib/python3.8/site-packages/django/template/base.py", line 938, in render
    bit = node.render_annotated(context)
  File "/Users/richellekyj/opt/anaconda3/lib/python3.8/site-packages/django/template/base.py", line 905, in render_annotated
    return self.render(context)
  File "/Users/richellekyj/opt/anaconda3/lib/python3.8/site-packages/django/template/library.py", line 192, in render
    output = self.func(*resolved_args, **resolved_kwargs)
  File "/Users/richellekyj/opt/anaconda3/lib/python3.8/site-packages/rest_framework/templatetags/rest_framework.py", line 81, in render_form
    return renderer.render(serializer.data, None, {'style': style})
AttributeError: 'str' object has no attribute 'data'
Internal Server Error: /registerUser/
Traceback (most recent call last):
  File "/Users/richellekyj/opt/anaconda3/lib/python3.8/site-packages/django/core/handlers/exception.py", line 47, in inner
    response = get_response(request)
  File "/Users/richellekyj/opt/anaconda3/lib/python3.8/site-packages/django/core/handlers/base.py", line 181, in _get_response
    response = wrapped_callback(request, *callback_args, **callback_kwargs)
  File "/Users/richellekyj/Documents/FYP/OAiES/registerUser/views.py", line 16, in registerUser
    return render(request, 'registerUser.html', context)
  File "/Users/richellekyj/opt/anaconda3/lib/python3.8/site-packages/django/shortcuts.py", line 19, in render
    content = loader.render_to_string(template_name, context, request, using=using)
  File "/Users/richellekyj/opt/anaconda3/lib/python3.8/site-packages/django/template/loader.py", line 62, in render_to_string
    return template.render(context, request)
  File "/Users/richellekyj/opt/anaconda3/lib/python3.8/site-packages/django/template/backends/django.py", line 61, in render
    return self.template.render(context)
  File "/Users/richellekyj/opt/anaconda3/lib/python3.8/site-packages/django/template/base.py", line 170, in render
    return self._render(context)
  File "/Users/richellekyj/opt/anaconda3/lib/python3.8/site-packages/django/template/base.py", line 162, in _render
    return self.nodelist.render(context)
  File "/Users/richellekyj/opt/anaconda3/lib/python3.8/site-packages/django/template/base.py", line 938, in render
    bit = node.render_annotated(context)
  File "/Users/richellekyj/opt/anaconda3/lib/python3.8/site-packages/django/template/base.py", line 905, in render_annotated
    return self.render(context)
  File "/Users/richellekyj/opt/anaconda3/lib/python3.8/site-packages/django/template/library.py", line 192, in render
    output = self.func(*resolved_args, **resolved_kwargs)
  File "/Users/richellekyj/opt/anaconda3/lib/python3.8/site-packages/rest_framework/templatetags/rest_framework.py", line 81, in render_form
    return renderer.render(serializer.data, None, {'style': style})
AttributeError: 'str' object has no attribute 'data'
Internal Server Error: /registerUser/
Traceback (most recent call last):
  File "/Users/richellekyj/opt/anaconda3/lib/python3.8/site-packages/django/core/handlers/exception.py", line 47, in inner
    response = get_response(request)
  File "/Users/richellekyj/opt/anaconda3/lib/python3.8/site-packages/django/core/handlers/base.py", line 181, in _get_response
    response = wrapped_callback(request, *callback_args, **callback_kwargs)
  File "/Users/richellekyj/Documents/FYP/OAiES/registerUser/views.py", line 16, in registerUser
    return render(request, 'registerUser.html', context)
  File "/Users/richellekyj/opt/anaconda3/lib/python3.8/site-packages/django/shortcuts.py", line 19, in render
    content = loader.render_to_string(template_name, context, request, using=using)
  File "/Users/richellekyj/opt/anaconda3/lib/python3.8/site-packages/django/template/loader.py", line 62, in render_to_string
    return template.render(context, request)
  File "/Users/richellekyj/opt/anaconda3/lib/python3.8/site-packages/django/template/backends/django.py", line 61, in render
    return self.template.render(context)
  File "/Users/richellekyj/opt/anaconda3/lib/python3.8/site-packages/django/template/base.py", line 170, in render
    return self._render(context)
  File "/Users/richellekyj/opt/anaconda3/lib/python3.8/site-packages/django/template/base.py", line 162, in _render
    return self.nodelist.render(context)
  File "/Users/richellekyj/opt/anaconda3/lib/python3.8/site-packages/django/template/base.py", line 938, in render
    bit = node.render_annotated(context)
  File "/Users/richellekyj/opt/anaconda3/lib/python3.8/site-packages/django/template/base.py", line 905, in render_annotated
    return self.render(context)
  File "/Users/richellekyj/opt/anaconda3/lib/python3.8/site-packages/django/template/library.py", line 192, in render
    output = self.func(*resolved_args, **resolved_kwargs)
  File "/Users/richellekyj/opt/anaconda3/lib/python3.8/site-packages/rest_framework/templatetags/rest_framework.py", line 81, in render_form
    return renderer.render(serializer.data, None, {'style': style})
AttributeError: 'str' object has no attribute 'data'
Internal Server Error: /registerUser/
Traceback (most recent call last):
  File "/Users/richellekyj/opt/anaconda3/lib/python3.8/site-packages/django/core/handlers/exception.py", line 47, in inner
    response = get_response(request)
  File "/Users/richellekyj/opt/anaconda3/lib/python3.8/site-packages/django/core/handlers/base.py", line 181, in _get_response
    response = wrapped_callback(request, *callback_args, **callback_kwargs)
  File "/Users/richellekyj/Documents/FYP/OAiES/registerUser/views.py", line 29, in registerUser
    return render(request, 'registerUser.html', context)
  File "/Users/richellekyj/opt/anaconda3/lib/python3.8/site-packages/django/shortcuts.py", line 19, in render
    content = loader.render_to_string(template_name, context, request, using=using)
  File "/Users/richellekyj/opt/anaconda3/lib/python3.8/site-packages/django/template/loader.py", line 62, in render_to_string
    return template.render(context, request)
  File "/Users/richellekyj/opt/anaconda3/lib/python3.8/site-packages/django/template/backends/django.py", line 61, in render
    return self.template.render(context)
  File "/Users/richellekyj/opt/anaconda3/lib/python3.8/site-packages/django/template/base.py", line 170, in render
    return self._render(context)
  File "/Users/richellekyj/opt/anaconda3/lib/python3.8/site-packages/django/template/base.py", line 162, in _render
    return self.nodelist.render(context)
  File "/Users/richellekyj/opt/anaconda3/lib/python3.8/site-packages/django/template/base.py", line 938, in render
    bit = node.render_annotated(context)
  File "/Users/richellekyj/opt/anaconda3/lib/python3.8/site-packages/django/template/base.py", line 905, in render_annotated
    return self.render(context)
  File "/Users/richellekyj/opt/anaconda3/lib/python3.8/site-packages/django/template/library.py", line 192, in render
    output = self.func(*resolved_args, **resolved_kwargs)
  File "/Users/richellekyj/opt/anaconda3/lib/python3.8/site-packages/rest_framework/templatetags/rest_framework.py", line 81, in render_form
    return renderer.render(serializer.data, None, {'style': style})
AttributeError: 'str' object has no attribute 'data'
Internal Server Error: /
Traceback (most recent call last):
  File "/Users/richellekyj/opt/anaconda3/lib/python3.8/site-packages/django/db/backends/utils.py", line 84, in _execute
    return self.cursor.execute(sql, params)
  File "/Users/richellekyj/opt/anaconda3/lib/python3.8/site-packages/django/db/backends/mysql/base.py", line 73, in execute
    return self.cursor.execute(query, args)
  File "/Users/richellekyj/opt/anaconda3/lib/python3.8/site-packages/MySQLdb/cursors.py", line 206, in execute
    res = self._query(query)
  File "/Users/richellekyj/opt/anaconda3/lib/python3.8/site-packages/MySQLdb/cursors.py", line 319, in _query
    db.query(q)
  File "/Users/richellekyj/opt/anaconda3/lib/python3.8/site-packages/MySQLdb/connections.py", line 259, in query
    _mysql.connection.query(self, query)
MySQLdb._exceptions.OperationalError: (1054, "Unknown column 'registerUser_user.role_id' in 'field list'")

The above exception was the direct cause of the following exception:

Traceback (most recent call last):
  File "/Users/richellekyj/opt/anaconda3/lib/python3.8/site-packages/django/core/handlers/exception.py", line 47, in inner
    response = get_response(request)
  File "/Users/richellekyj/opt/anaconda3/lib/python3.8/site-packages/django/core/handlers/base.py", line 181, in _get_response
    response = wrapped_callback(request, *callback_args, **callback_kwargs)
  File "/Users/richellekyj/Documents/FYP/OAiES/main/views.py", line 6, in landing_view
    return render(request, "landingpage.html", {})
  File "/Users/richellekyj/opt/anaconda3/lib/python3.8/site-packages/django/shortcuts.py", line 19, in render
    content = loader.render_to_string(template_name, context, request, using=using)
  File "/Users/richellekyj/opt/anaconda3/lib/python3.8/site-packages/django/template/loader.py", line 62, in render_to_string
    return template.render(context, request)
  File "/Users/richellekyj/opt/anaconda3/lib/python3.8/site-packages/django/template/backends/django.py", line 61, in render
    return self.template.render(context)
  File "/Users/richellekyj/opt/anaconda3/lib/python3.8/site-packages/django/template/base.py", line 170, in render
    return self._render(context)
  File "/Users/richellekyj/opt/anaconda3/lib/python3.8/site-packages/django/template/base.py", line 162, in _render
    return self.nodelist.render(context)
  File "/Users/richellekyj/opt/anaconda3/lib/python3.8/site-packages/django/template/base.py", line 938, in render
    bit = node.render_annotated(context)
  File "/Users/richellekyj/opt/anaconda3/lib/python3.8/site-packages/django/template/base.py", line 905, in render_annotated
    return self.render(context)
  File "/Users/richellekyj/opt/anaconda3/lib/python3.8/site-packages/django/template/loader_tags.py", line 195, in render
    return template.render(context)
  File "/Users/richellekyj/opt/anaconda3/lib/python3.8/site-packages/django/template/base.py", line 172, in render
    return self._render(context)
  File "/Users/richellekyj/opt/anaconda3/lib/python3.8/site-packages/django/template/base.py", line 162, in _render
    return self.nodelist.render(context)
  File "/Users/richellekyj/opt/anaconda3/lib/python3.8/site-packages/django/template/base.py", line 938, in render
    bit = node.render_annotated(context)
  File "/Users/richellekyj/opt/anaconda3/lib/python3.8/site-packages/django/template/base.py", line 905, in render_annotated
    return self.render(context)
  File "/Users/richellekyj/opt/anaconda3/lib/python3.8/site-packages/django/template/defaulttags.py", line 305, in render
    match = condition.eval(context)
  File "/Users/richellekyj/opt/anaconda3/lib/python3.8/site-packages/django/template/defaulttags.py", line 889, in eval
    return self.value.resolve(context, ignore_failures=True)
  File "/Users/richellekyj/opt/anaconda3/lib/python3.8/site-packages/django/template/base.py", line 671, in resolve
    obj = self.var.resolve(context)
  File "/Users/richellekyj/opt/anaconda3/lib/python3.8/site-packages/django/template/base.py", line 796, in resolve
    value = self._resolve_lookup(context)
  File "/Users/richellekyj/opt/anaconda3/lib/python3.8/site-packages/django/template/base.py", line 829, in _resolve_lookup
    current = current[bit]
  File "/Users/richellekyj/opt/anaconda3/lib/python3.8/site-packages/django/utils/functional.py", line 246, in inner
    self._setup()
  File "/Users/richellekyj/opt/anaconda3/lib/python3.8/site-packages/django/utils/functional.py", line 382, in _setup
    self._wrapped = self._setupfunc()
  File "/Users/richellekyj/opt/anaconda3/lib/python3.8/site-packages/django/contrib/auth/middleware.py", line 23, in <lambda>
    request.user = SimpleLazyObject(lambda: get_user(request))
  File "/Users/richellekyj/opt/anaconda3/lib/python3.8/site-packages/django/contrib/auth/middleware.py", line 11, in get_user
    request._cached_user = auth.get_user(request)
  File "/Users/richellekyj/opt/anaconda3/lib/python3.8/site-packages/django/contrib/auth/__init__.py", line 184, in get_user
    user = backend.get_user(user_id)
  File "/Users/richellekyj/opt/anaconda3/lib/python3.8/site-packages/django/contrib/auth/backends.py", line 157, in get_user
    user = UserModel._default_manager.get(pk=user_id)
  File "/Users/richellekyj/opt/anaconda3/lib/python3.8/site-packages/django/db/models/manager.py", line 85, in manager_method
    return getattr(self.get_queryset(), name)(*args, **kwargs)
  File "/Users/richellekyj/opt/anaconda3/lib/python3.8/site-packages/django/db/models/query.py", line 431, in get
    num = len(clone)
  File "/Users/richellekyj/opt/anaconda3/lib/python3.8/site-packages/django/db/models/query.py", line 262, in __len__
    self._fetch_all()
  File "/Users/richellekyj/opt/anaconda3/lib/python3.8/site-packages/django/db/models/query.py", line 1324, in _fetch_all
    self._result_cache = list(self._iterable_class(self))
  File "/Users/richellekyj/opt/anaconda3/lib/python3.8/site-packages/django/db/models/query.py", line 51, in __iter__
    results = compiler.execute_sql(chunked_fetch=self.chunked_fetch, chunk_size=self.chunk_size)
  File "/Users/richellekyj/opt/anaconda3/lib/python3.8/site-packages/django/db/models/sql/compiler.py", line 1169, in execute_sql
    cursor.execute(sql, params)
  File "/Users/richellekyj/opt/anaconda3/lib/python3.8/site-packages/django/db/backends/utils.py", line 98, in execute
    return super().execute(sql, params)
  File "/Users/richellekyj/opt/anaconda3/lib/python3.8/site-packages/django/db/backends/utils.py", line 66, in execute
    return self._execute_with_wrappers(sql, params, many=False, executor=self._execute)
  File "/Users/richellekyj/opt/anaconda3/lib/python3.8/site-packages/django/db/backends/utils.py", line 75, in _execute_with_wrappers
    return executor(sql, params, many, context)
  File "/Users/richellekyj/opt/anaconda3/lib/python3.8/site-packages/django/db/backends/utils.py", line 84, in _execute
    return self.cursor.execute(sql, params)
  File "/Users/richellekyj/opt/anaconda3/lib/python3.8/site-packages/django/db/utils.py", line 90, in __exit__
    raise dj_exc_value.with_traceback(traceback) from exc_value
  File "/Users/richellekyj/opt/anaconda3/lib/python3.8/site-packages/django/db/backends/utils.py", line 84, in _execute
    return self.cursor.execute(sql, params)
  File "/Users/richellekyj/opt/anaconda3/lib/python3.8/site-packages/django/db/backends/mysql/base.py", line 73, in execute
    return self.cursor.execute(query, args)
  File "/Users/richellekyj/opt/anaconda3/lib/python3.8/site-packages/MySQLdb/cursors.py", line 206, in execute
    res = self._query(query)
  File "/Users/richellekyj/opt/anaconda3/lib/python3.8/site-packages/MySQLdb/cursors.py", line 319, in _query
    db.query(q)
  File "/Users/richellekyj/opt/anaconda3/lib/python3.8/site-packages/MySQLdb/connections.py", line 259, in query
    _mysql.connection.query(self, query)
django.db.utils.OperationalError: (1054, "Unknown column 'registerUser_user.role_id' in 'field list'")
